<?xml version="1.0" ?>
<sdf version="1.5">
    <model name="basic_mobile_bot">
        <static>false</static>

        <!-- ****************** ROBOT BASE FOOTPRINT ***************************  -->
        <pose>0.0 0.0 0.0 0.0 0.0 0.0</pose>
        <link name="base_footprint"/>

        <!-- ********************** ROBOT BASE *********************************  -->
        <link name="base_link">

            <collision name="base_collision">
                <pose>0 0 0.1 0 0 0</pose>
                <geometry>
                    <box>
                        <size>0.70 0.39 0.20</size>
                    </box>
                </geometry>
            </collision>

            <visual name="base_visual">
                <pose>0 0 -0.05 1.5707963267949 0 3.141592654</pose>
                <geometry>
                    <mesh>
                        <!-- <uri>model://vehicle_2/meshes/robot_base.stl</uri> -->
                        <uri>file:///home/user/wasp_ws/src/tutorials/ign_tutorial/models/vehicle_2/meshes/robot_base.stl</uri>
                        <scale>1.0 1.0 1.0</scale>
                    </mesh>
                </geometry>
                <material>
                    <ambient>1.0 0.0 0.0 1.0</ambient>
                    <diffuse>1.0 0.0 0.0 1.0</diffuse>
                    <specular>0.0 0.0 0.0 1.0</specular>
                    <emissive>0.0 0.0 0.0 1.0</emissive>
                </material>
            </visual>
        </link>

        <!-- *********************** IMU SENSOR SETUP **************************  -->
        <link name="imu_link">
            <gravity>true</gravity>
            <sensor name="bmb_imu" type="imu">
                <always_on>true</always_on>
                <update_rate>100</update_rate>
                <visualize>true</visualize>
                <imu>
                    <orientation>
                        <x>
                            <noise type="gaussian">
                                <mean>0.0</mean>
                                <stddev>2e-3</stddev>
                            </noise>
                        </x>
                        <y>
                            <noise type="gaussian">
                                <mean>0.0</mean>
                                <stddev>2e-3</stddev>
                            </noise>
                        </y>
                        <z>
                            <noise type="gaussian">
                                <mean>0.0</mean>
                                <stddev>2e-3</stddev>
                            </noise>
                        </z>
                    </orientation>
                    <angular_velocity>
                        <x>
                            <noise type="gaussian">
                                <mean>0.0</mean>
                                <stddev>2e-4</stddev>
                            </noise>
                        </x>
                        <y>
                            <noise type="gaussian">
                                <mean>0.0</mean>
                                <stddev>2e-4</stddev>
                            </noise>
                        </y>
                        <z>
                            <noise type="gaussian">
                                <mean>0.0</mean>
                                <stddev>2e-4</stddev>
                            </noise>
                        </z>
                    </angular_velocity>
                    <linear_acceleration>
                        <x>
                            <noise type="gaussian">
                                <mean>0.0</mean>
                                <stddev>1.7e-2</stddev>
                            </noise>
                        </x>
                        <y>
                            <noise type="gaussian">
                                <mean>0.0</mean>
                                <stddev>1.7e-2</stddev>
                            </noise>
                        </y>
                        <z>
                            <noise type="gaussian">
                                <mean>0.0</mean>
                                <stddev>1.7e-2</stddev>
                            </noise>
                        </z>
                    </linear_acceleration>
                </imu>
                <!-- <plugin name="basic_mobile_bot_imu" filename="libgazebo_ros_imu_sensor.so">
                    <initial_orientation_as_reference>false</initial_orientation_as_reference>
                    <frame_name>imu_link</frame_name>
                    <ros>
                        <namespace>/imu</namespace>
                        <remapping>~/out:=data</remapping>
                    </ros>
                </plugin> -->
            </sensor>
        </link>

        <!-- *********************** GPS SETUP *********************************  -->
        <link name="gps_link">
            <sensor name="bmb_gps" type="gps">
                <always_on>true</always_on>
                <update_rate>10.0</update_rate>
                <gps>
                    <position_sensing>
                        <horizontal>
                            <noise type="gaussian">
                                <mean>0.0</mean>
                                <stddev>1e-2</stddev>
                            </noise>
                        </horizontal>
                        <vertical>
                            <noise type="gaussian">
                                <mean>0.0</mean>
                                <stddev>1</stddev>
                            </noise>
                        </vertical>
                    </position_sensing>
                </gps>
                <!-- <plugin name="basic_mobile_bot_gps" filename="libgazebo_ros_gps_sensor.so">
                    <ros>
                        <remapping>~/out:=gps/fix</remapping>
                    </ros>
                </plugin> -->
            </sensor>
        </link>

        <!-- *********************** DRIVE WHEELS ******************************  -->
        <link name="drivewhl_l_link">
            <pose>-0.221 0.23 -0.05 0 1.570796 1.570796</pose>

            <collision name="drivewhl_l_collision">
                <geometry>
                    <cylinder>
                        <radius>0.14</radius>
                        <length>0.06</length>
                    </cylinder>
                </geometry>
            </collision>

            <visual name="drivewhl_l_visual">
                <geometry>
                    <cylinder>
                        <radius>0.14</radius>
                        <length>0.06</length>
                    </cylinder>
                </geometry>
            </visual>
        </link>

        <link name="drivewhl_r_link">
            <pose>-0.221 -0.23 -0.05 0 1.570796 1.570796</pose>

            <collision name="drivewhl_r_collision">
                <geometry>
                    <cylinder>
                        <radius>0.14</radius>
                        <length>0.06</length>
                    </cylinder>
                </geometry>
            </collision>

            <visual name="drivewhl_r_visual">
                <geometry>
                    <cylinder>
                        <radius>0.14</radius>
                        <length>0.06</length>
                    </cylinder>
                </geometry>
            </visual>
        </link>

        <!-- *********************** CASTER WHEEL ******************************  -->
        <link name='front_caster'>
            <pose>0.217 0 -0.1 0 0 0</pose>
            <collision name='collision'>
                <geometry>
                    <sphere>
                        <radius>0.09</radius>
                    </sphere>
                </geometry>
                <surface>
                    <friction>
                        <ode>
                            <mu>0.01</mu>
                            <mu2>0.01</mu2>
                            <slip1>1.0</slip1>
                            <slip2>1.0</slip2>
                        </ode>
                    </friction>
                </surface>
            </collision>
            <visual name="front_caster_visual">
                <geometry>
                    <sphere>
                        <radius>0.09</radius>
                    </sphere>
                </geometry>
            </visual>
        </link>

        <!-- ************************ JOINTS ***********************************  -->
        <!-- Pose of the joint is the same as the child link frame -->
        <!-- Axis is the axis of rotation relative to the child link frame -->

        <joint name="base_joint" type="fixed">
            <parent>base_footprint</parent>
            <child>base_link</child>
            <pose>0 0 0 0 0 0</pose>
        </joint>

        <joint name="drivewhl_l_joint" type="revolute">
            <parent>base_link</parent>
            <child>drivewhl_l_link</child>
            <pose>0 0 0 0 0 0</pose>
            <axis>
                <xyz>0 0 1</xyz>
            </axis>
        </joint>

        <joint name="drivewhl_r_joint" type="revolute">
            <parent>base_link</parent>
            <child>drivewhl_r_link</child>
            <pose>0 0 0 0 0 0</pose>
            <axis>
                <xyz>0 0 1</xyz>
            </axis>
        </joint>

        <joint name='caster_joint' type='fixed'>
            <parent>base_link</parent>
            <child>front_caster</child>
            <pose>0 0 0 0 0 0</pose>
        </joint>

        <joint name="imu_joint" type="fixed">
            <parent>base_link</parent>
            <child>imu_link</child>
            <pose>0 0 0 0 0 0</pose>
        </joint>

        <joint name="gps_joint" type="fixed">
            <parent>base_link</parent>
            <child>gps_link</child>
            <pose>0 0 0 0 0 0</pose>
        </joint>

        <plugin filename="libignition-gazebo-joint-state-publisher-system.so" name="ignition::gazebo::systems::JointStatePublisher">
        </plugin>
    </model>
</sdf>