<?xml version="1.0" ?>
<sdf version="1.5">
    <model name="basic_mobile_bot">
        <static>false</static>

        <!-- ****************** ROBOT BASE FOOTPRINT ***************************  -->
        <pose>0.0 0.0 0.0 0.0 0.0 0.0</pose>
        <link name="base_footprint"/>

        <!-- ********************** ROBOT BASE *********************************  -->
        <link name="base_link">

            <collision name="base_collision">
                <pose>0 0 0.1 0 0 0</pose>
                <geometry>
                    <box>
                        <size>0.70 0.39 0.20</size>
                    </box>
                </geometry>
            </collision>

            <visual name="base_visual">
                <pose>0 0 -0.05 1.5707963267949 0 3.141592654</pose>
                <geometry>
                    <mesh>
                        <!-- <uri>model://vehicle_2/meshes/robot_base.stl</uri> -->
                        <uri>file:///home/user/wasp_ws/src/tutorials/ign_tutorial/models/vehicle_2/meshes/robot_base.stl</uri>
                        <scale>1.0 1.0 1.0</scale>
                    </mesh>
                </geometry>
                <material>
                    <ambient>1.0 0.0 0.0 1.0</ambient>
                    <diffuse>1.0 0.0 0.0 1.0</diffuse>
                    <specular>0.0 0.0 0.0 1.0</specular>
                    <emissive>0.0 0.0 0.0 1.0</emissive>
                </material>
            </visual>
        </link>

        <!-- *********************** IMU SENSOR SETUP **************************  -->
        <link name="imu_link">
            <gravity>true</gravity>
            <sensor name="imu" type="imu">
                <always_on>1</always_on>
                <update_rate>50</update_rate>
                <visualize>true</visualize>
                <topic>imu</topic>
                <enable_metrics>true</enable_metrics>
            </sensor>
        </link>

        <!-- *********************** GPS SETUP *********************************  -->
        <link name="gps_link">
            <sensor name="bmb_gps" type="gps">
                <always_on>true</always_on>
                <update_rate>10.0</update_rate>
                <gps>
                    <position_sensing>
                        <horizontal>
                            <noise type="gaussian">
                                <mean>0.0</mean>
                                <stddev>1e-2</stddev>
                            </noise>
                        </horizontal>
                        <vertical>
                            <noise type="gaussian">
                                <mean>0.0</mean>
                                <stddev>1</stddev>
                            </noise>
                        </vertical>
                    </position_sensing>
                </gps>
                <!-- <plugin name="basic_mobile_bot_gps" filename="libgazebo_ros_gps_sensor.so">
                    <ros>
                        <remapping>~/out:=gps/fix</remapping>
                    </ros>
                </plugin> -->
            </sensor>
        </link>

        <!-- *********************** DRIVE WHEELS ******************************  -->
        <link name="drivewhl_l_link">
            <pose>-0.221 0.23 -0.05 0 1.570796 1.570796</pose>

            <collision name="drivewhl_l_collision">
                <geometry>
                    <cylinder>
                        <radius>0.14</radius>
                        <length>0.06</length>
                    </cylinder>
                </geometry>
            </collision>

            <visual name="drivewhl_l_visual">
                <geometry>
                    <cylinder>
                        <radius>0.14</radius>
                        <length>0.06</length>
                    </cylinder>
                </geometry>
            </visual>
        </link>

        <link name="drivewhl_r_link">
            <pose>-0.221 -0.23 -0.05 0 1.570796 1.570796</pose>

            <collision name="drivewhl_r_collision">
                <geometry>
                    <cylinder>
                        <radius>0.14</radius>
                        <length>0.06</length>
                    </cylinder>
                </geometry>
            </collision>

            <visual name="drivewhl_r_visual">
                <geometry>
                    <cylinder>
                        <radius>0.14</radius>
                        <length>0.06</length>
                    </cylinder>
                </geometry>
            </visual>
        </link>

        <!-- *********************** CASTER WHEEL ******************************  -->
        <link name='front_caster'>
            <pose>0.217 0 -0.1 0 0 0</pose>
            <collision name='collision'>
                <geometry>
                    <sphere>
                        <radius>0.09</radius>
                    </sphere>
                </geometry>
                <surface>
                    <friction>
                        <ode>
                            <mu>0.01</mu>
                            <mu2>0.01</mu2>
                            <slip1>1.0</slip1>
                            <slip2>1.0</slip2>
                        </ode>
                    </friction>
                </surface>
            </collision>
            <visual name="front_caster_visual">
                <geometry>
                    <sphere>
                        <radius>0.09</radius>
                    </sphere>
                </geometry>
            </visual>
        </link>

        <link name="lidar_link">
            <inertial>
                <pose>0.215 0 0.13 0 0 0</pose>
                <inertia>
                    <ixx>0.001</ixx>
                    <ixy>0.000</ixy>
                    <ixz>0.000</ixz>
                    <iyy>0.001</iyy>
                    <iyz>0.000</iyz>
                    <izz>0.001</izz>
                </inertia>
                <mass>0.114</mass>
            </inertial>

            <collision name="lidar_collision">
                <pose>0.215 0 0.13 0 0 0</pose>
                <geometry>
                    <cylinder>
                        <radius>0.0508</radius>
                        <length>0.18</length>
                    </cylinder>
                </geometry>
            </collision>
            <visual name="lidar_visual">
                <pose>0.215 0 0.13 0 0 0</pose>
                <geometry>
                    <cylinder>
                        <radius>0.0508</radius>
                        <length>0.18</length>
                    </cylinder>
                </geometry>
                <material>
                    <ambient>0.0 0.0 0.0 1.0</ambient>
                    <diffuse>0.0 0.0 0.0 1.0</diffuse>
                    <specular>0.0 0.0 0.0 1.0</specular>
                    <emissive>0.0 0.0 0.0 1.0</emissive>
                </material>
            </visual>
            <sensor name='gpu_lidar' type='gpu_lidar'>
                <topic>lidar</topic>
                <update_rate>10</update_rate>
                <lidar>
                    <scan>
                        <horizontal>
                            <samples>640</samples>
                            <resolution>1</resolution>
                            <min_angle>-1.396263</min_angle>
                            <max_angle>1.396263</max_angle>
                        </horizontal>
                        <vertical>
                            <samples>16</samples>
                            <resolution>1</resolution>
                            <min_angle>-0.261799</min_angle>
                            <max_angle>0.261799</max_angle>
                        </vertical>
                    </scan>
                    <range>
                        <min>0.08</min>
                        <max>10.0</max>
                        <resolution>0.01</resolution>
                    </range>
                </lidar>
                <alwaysOn>1</alwaysOn>
                <visualize>true</visualize>
            </sensor>
        </link>
        <!-- ************************ JOINTS ***********************************  -->
        <!-- Pose of the joint is the same as the child link frame -->
        <!-- Axis is the axis of rotation relative to the child link frame -->

        <joint name="base_joint" type="fixed">
            <parent>base_footprint</parent>
            <child>base_link</child>
            <pose>0 0 0 0 0 0</pose>
        </joint>

        <joint name="drivewhl_l_joint" type="revolute">
            <parent>base_link</parent>
            <child>drivewhl_l_link</child>
            <pose>0 0 0 0 0 0</pose>
            <axis>
                <xyz>0 0 1</xyz>
            </axis>
        </joint>

        <joint name="drivewhl_r_joint" type="revolute">
            <parent>base_link</parent>
            <child>drivewhl_r_link</child>
            <pose>0 0 0 0 0 0</pose>
            <axis>
                <xyz>0 0 1</xyz>
            </axis>
        </joint>

        <joint name='caster_joint' type='fixed'>
            <parent>base_link</parent>
            <child>front_caster</child>
            <pose>0 0 0 0 0 0</pose>
        </joint>

        <joint name="imu_joint" type="fixed">
            <parent>base_link</parent>
            <child>imu_link</child>
            <pose>0 0 0 0 0 0</pose>
        </joint>

        <joint name="gps_joint" type="fixed">
            <parent>base_link</parent>
            <child>gps_link</child>
            <pose>0 0 0 0 0 0</pose>
        </joint>

        <joint name="lidar_joint" type="fixed">
            <parent>base_link</parent>
            <child>lidar_link</child>
            <pose>0 0 0 0 0 0</pose>
        </joint>

        <plugin filename="libignition-gazebo-joint-state-publisher-system.so" name="ignition::gazebo::systems::JointStatePublisher">
        </plugin>
        <plugin filename="ignition-gazebo-diff-drive-system" name="ignition::gazebo::systems::DiffDrive">
            <left_joint>drivewhl_l_joint</left_joint>
            <right_joint>drivewhl_r_joint</right_joint>
            <wheel_separation>0.46</wheel_separation>
            <wheel_radius>0.14</wheel_radius>
            <frame_id>odom</frame_id>
            <child_frame_id>base_footprint</child_frame_id>
        </plugin>
    </model>
</sdf>